Workbook

Sheet ArticleData
A1: DATE | B1: Argentina | C1: Argentina | D1: Argentina | E1: Australia | F1: Australia | G1: Australia | H1: Brazil | I1: Brazil | J1: Brazil | K1: Canada | L1: Canada | M1: Canada | N1: China | O1: China | P1: China | Q1: France | R1: France | S1: France | T1: Germany | U1: Germany | V1: Germany | W1: India | X1: India | Y1: India | Z1: Indonesia | AA1: Indonesia | AB1: Indonesia | AC1: Italy | AD1: Italy | AE1: Italy | AF1: Japan | AG1: Japan | AH1: Japan | AI1: Mexico | AJ1: Mexico | AK1: Mexico | AL1: Russia | AM1: Russia | AN1: Russia | AO1: SouthAfrica | AP1: SouthAfrica | AQ1: SouthAfrica | AR1: SouthKorea | AS1: SouthKorea | AT1: SouthKorea | AU1: Turkiye | AV1: Turkiye | AW1: Turkiye | AX1: UK | AY1: UK | AZ1: UK | BA1: US | BB1: US | BC1: US
A2: YEAR | B2: Deflator | C2: RealGDP | D2: M3LogDiff | E2: Deflator | F2: RealGDP | G2: M3LogDiff | H2: Deflator | I2: RealGDP | J2: M3LogDiff | K2: Deflator | L2: RealGDP | M2: M3LogDiff | N2: Deflator | O2: RealGDP | P2: M3LogDiff | Q2: Deflator | R2: RealGDP | S2: M3LogDiff | T2: Deflator | U2: RealGDP | V2: M3LogDiff | W2: Deflator | X2: RealGDP | Y2: M3LogDiff | Z2: Deflator | AA2: RealGDP | AB2: M3LogDiff | AC2: Deflator | AD2: RealGDP | AE2: M3LogDiff | AF2: Deflator | AG2: RealGDP | AH2: M3LogDiff | AI2: Deflator | AJ2: RealGDP | AK2: M3LogDiff | AL2: Deflator | AM2: RealGDP | AN2: M3LogDiff | AO2: Deflator | AP2: RealGDP | AQ2: M3LogDiff | AR2: Deflator | AS2: RealGDP | AT2: M3LogDiff | AU2: Deflator | AV2: RealGDP | AW2: M3LogDiff | AX2: Deflator | AY2: RealGDP | AZ2: M3LogDiff | BA2: Deflator | BB2: RealGDP | BC2: M3LogDiff
A3: 2000 | B3: =+PercentageChange!B3-PercentageChange!C3 -> 1.0319442 | C3: =(LN(RawData!C4)-LN(RawData!C3))*100 -> -0.79212801 | D3: =+PercentageChange!D3-PercentageChange!C3 -> 4.4087985 | E3: =+PercentageChange!E3-PercentageChange!F3 -> 2.5187618 | F3: =(LN(RawData!F4)-LN(RawData!F3))*100 -> 3.8465792 | G3: =+PercentageChange!G3-PercentageChange!F3 -> 2.9945307 | H3: =+PercentageChange!H3-PercentageChange!I3 -> 5.4545619 | I3: =(LN(RawData!I4)-LN(RawData!I3))*100 -> 4.2944056 | J3: =+PercentageChange!J3-PercentageChange!I3 -> 17.074495 | K3: =+PercentageChange!K3-PercentageChange!L3 -> 4.2812323 | L3: =(LN(RawData!L4)-LN(RawData!L3))*100 -> 5.0108715 | M3: =+PercentageChange!M3-PercentageChange!L3 -> 2.3368995 | N3: =+PercentageChange!N3-PercentageChange!O3 -> 2.0418052 | O3: =(LN(RawData!O4)-LN(RawData!O3))*100 -> 8.1488678 | P3: =+PercentageChange!P3-PercentageChange!O3 -> 4.1863809 | Q3: =+PercentageChange!Q3-PercentageChange!R3 -> 1.5413502 | R3: =(LN(RawData!R4)-LN(RawData!R3))*100 -> 3.8486494 | S3: =+PercentageChange!S3-PercentageChange!R3 -> 1.6670046 | T3: =+PercentageChange!T3-PercentageChange!U3 -> -0.49059043 | U3: =(LN(RawData!U4)-LN(RawData!U3))*100 -> 2.8708955 | V3: =+PercentageChange!V3-PercentageChange!U3 -> 2.6447585 | W3: =+PercentageChange!W3-PercentageChange!X3 -> 3.5801125 | X3: =(LN(RawData!X4)-LN(RawData!X3))*100 -> 3.7690612 | Y3: =+PercentageChange!Y3-PercentageChange!X3 -> 10.86039 | Z3: =+PercentageChange!Z3-PercentageChange!AA3 -> 18.604343 | AA3: =(LN(RawData!AA4)-LN(RawData!AA3))*100 -> 4.8028615 | AB3: =+PercentageChange!AB3-PercentageChange!AA3 -> 4.628279 | AC3: =+PercentageChange!AC3-PercentageChange!AD3 -> 1.7765239 | AD3: =(LN(RawData!AD4)-LN(RawData!AD3))*100 -> 3.7170104 | AE3: =+PercentageChange!AE3-PercentageChange!AD3 -> 1.7986436 | AF3: =+PercentageChange!AF3-PercentageChange!AG3 -> -1.3452684 | AG3: =(LN(RawData!AG4)-LN(RawData!AG3))*100 -> 2.7271212 | AH3: =+PercentageChange!AH3-PercentageChange!AG3 -> -0.80127823 | AI3: =+PercentageChange!AI3-PercentageChange!AJ3 -> 10.163527 | AJ3: =(LN(RawData!AJ4)-LN(RawData!AJ3))*100 -> 4.906902 | AK3: =+PercentageChange!AK3-PercentageChange!AJ3 -> 14.349339 | AL3: =+PercentageChange!AL3-PercentageChange!AM3 -> 31.989217 | AM3: =(LN(RawData!AM4)-LN(RawData!AM3))*100 -> 9.5310787 | AN3: =+PercentageChange!AN3-PercentageChange!AM3 -> 37.487118 | AO3: =+PercentageChange!AO3-PercentageChange!AP3 -> 8.7847782 | AP3: =(LN(RawData!AP4)-LN(RawData!AP3))*100 -> 4.1141943 | AQ3: =+PercentageChange!AQ3-PercentageChange!AP3 -> 3.9960282 | AR3: =+PercentageChange!AR3-PercentageChange!AS3 -> 1.0165803 | AS3: =(LN(RawData!AS4)-LN(RawData!AS3))*100 -> 8.6735644 | AT3: =+PercentageChange!AT3-PercentageChange!AS3 -> -3.0673438 | AU3: =+PercentageChange!AU3-PercentageChange!AV3 -> 40.119451 | AV3: =(LN(RawData!AV4)-LN(RawData!AV3))*100 -> 6.7034526 | AW3: =+PercentageChange!AW3-PercentageChange!AV3 -> 46.30079 | AX3: =+PercentageChange!AX3-PercentageChange!AY3 -> 1.1373949 | AY3: =(LN(RawData!AY4)-LN(RawData!AY3))*100 -> 4.228071 | AZ3: =+PercentageChange!AZ3-PercentageChange!AY3 -> 3.5537217 | BA3: =+PercentageChange!BA3-PercentageChange!BB3 -> 2.2399206 | BB3: =(LN(RawData!BB4)-LN(RawData!BB3))*100 -> 3.9966452 | BC3: =+PercentageChange!BC3-PercentageChange!BB3 -> 1.9000676
A4: 2001 | B4: =+PercentageChange!B4-PercentageChange!C4 -> -1.1018155 | C4: =(LN(RawData!C5)-LN(RawData!C4))*100 -> -4.5089836 | D4: =+PercentageChange!D4-PercentageChange!C4 -> -4.1957091 | E4: =+PercentageChange!E4-PercentageChange!F4 -> 4.5266996 | F4: =(LN(RawData!F5)-LN(RawData!F4))*100 -> 2.0048943 | G4: =+PercentageChange!G4-PercentageChange!F4 -> 6.4697836 | H4: =+PercentageChange!H4-PercentageChange!I4 -> 7.9043079 | I4: =(LN(RawData!I5)-LN(RawData!I4))*100 -> 1.3803259 | J4: =+PercentageChange!J4-PercentageChange!I4 -> 12.626752 | K4: =+PercentageChange!K4-PercentageChange!L4 -> 1.5614229 | L4: =(LN(RawData!L5)-LN(RawData!L4))*100 -> 1.8577349 | M4: =+PercentageChange!M4-PercentageChange!L4 -> 3.5178857 | N4: =+PercentageChange!N4-PercentageChange!O4 -> 2.026379 | O4: =(LN(RawData!O5)-LN(RawData!O4))*100 -> 8.0064863 | P4: =+PercentageChange!P4-PercentageChange!O4 -> 6.3170954 | Q4: =+PercentageChange!Q4-PercentageChange!R4 -> 1.9884332 | R4: =(LN(RawData!R5)-LN(RawData!R4))*100 -> 1.9643021 | S4: =+PercentageChange!S4-PercentageChange!R4 -> 6.1084135 | T4: =+PercentageChange!T4-PercentageChange!U4 -> 1.2965532 | U4: =(LN(RawData!U5)-LN(RawData!U4))*100 -> 1.6674883 | V4: =+PercentageChange!V4-PercentageChange!U4 -> 6.4052272 | W4: =+PercentageChange!W4-PercentageChange!X4 -> 3.1649974 | X4: =(LN(RawData!X5)-LN(RawData!X4))*100 -> 4.7112245 | Y4: =+PercentageChange!Y4-PercentageChange!X4 -> 10.672512 | Z4: =+PercentageChange!Z4-PercentageChange!AA4 -> 13.36189 | AA4: =(LN(RawData!AA5)-LN(RawData!AA4))*100 -> 3.5786616 | AB4: =+PercentageChange!AB4-PercentageChange!AA4 -> 10.141627 | AC4: =+PercentageChange!AC4-PercentageChange!AD4 -> 2.9884885 | AD4: =(LN(RawData!AD5)-LN(RawData!AD4))*100 -> 1.9325764 | AE4: =+PercentageChange!AE4-PercentageChange!AD4 -> 6.1401391 | AF4: =+PercentageChange!AF4-PercentageChange!AG4 -> -1.0908076 | AG4: =(LN(RawData!AG5)-LN(RawData!AG4))*100 -> 0.38535996 | AH4: =+PercentageChange!AH4-PercentageChange!AG4 -> 1.20294 | AI4: =+PercentageChange!AI4-PercentageChange!AJ4 -> 6.2721332 | AJ4: =(LN(RawData!AJ5)-LN(RawData!AJ4))*100 -> -0.45186463 | AK4: =+PercentageChange!AK4-PercentageChange!AJ4 -> 25.281144 | AL4: =+PercentageChange!AL4-PercentageChange!AM4 -> 15.254613 | AM4: =(LN(RawData!AM5)-LN(RawData!AM4))*100 -> 4.9742579 | AN4: =+PercentageChange!AN4-PercentageChange!AM4 -> 32.429557 | AO4: =+PercentageChange!AO4-PercentageChange!AP4 -> 7.5111878 | AP4: =(LN(RawData!AP5)-LN(RawData!AP4))*100 -> 2.6641931 | AQ4: =+PercentageChange!AQ4-PercentageChange!AP4 -> 10.878043 | AR4: =+PercentageChange!AR4-PercentageChange!AS4 -> 3.4193667 | AS4: =(LN(RawData!AS5)-LN(RawData!AS4))*100 -> 4.7383457 | AT4: =+PercentageChange!AT4-PercentageChange!AS4 -> 4.3265417 | AU4: =+PercentageChange!AU4-PercentageChange!AV4 -> 42.513544 | AV4: =(LN(RawData!AV5)-LN(RawData!AV4))*100 -> -5.9219429 | AW4: =+PercentageChange!AW4-PercentageChange!AV4 -> 61.603819 | AX4: =+PercentageChange!AX4-PercentageChange!AY4 -> 1.4941307 | AY4: =(LN(RawData!AY5)-LN(RawData!AY4))*100 -> 2.5460523 | AZ4: =+PercentageChange!AZ4-PercentageChange!AY4 -> 7.1981539 | BA4: =+PercentageChange!BA4-PercentageChange!BB4 -> 2.2267136 | BB4: =(LN(RawData!BB5)-LN(RawData!BB4))*100 -> 0.95100195 | BC4: =+PercentageChange!BC4-PercentageChange!BB4 -> 7.3993302
A5: 2002 | B5: =+PercentageChange!B5-PercentageChange!C5 -> 26.662597 | C5: =(LN(RawData!C6)-LN(RawData!C5))*100 -> -11.534895 | D5: =+PercentageChange!D5-PercentageChange!C5 -> 2.7314381 | E5: =+PercentageChange!E5-PercentageChange!F5 -> 2.8007181 | F5: =(LN(RawData!F6)-LN(RawData!F5))*100 -> 3.9024865 | G5: =+PercentageChange!G5-PercentageChange!F5 -> 4.5230462 | H5: =+PercentageChange!H5-PercentageChange!I5 -> 9.347315 | I5: =(LN(RawData!I6)-LN(RawData!I5))*100 -> 3.0077715 | J5: =+PercentageChange!J5-PercentageChange!I5 -> 6.3751724 | K5: =+PercentageChange!K5-PercentageChange!L5 -> 1.2496823 | L5: =(LN(RawData!L6)-LN(RawData!L5))*100 -> 2.9551573 | M5: =+PercentageChange!M5-PercentageChange!L5 -> 2.8194412 | N5: =+PercentageChange!N5-PercentageChange!O5 -> 0.6002937 | O5: =(LN(RawData!O6)-LN(RawData!O5))*100 -> 8.7402916 | P5: =+PercentageChange!P5-PercentageChange!O5 -> 6.755653 | Q5: =+PercentageChange!Q5-PercentageChange!R5 -> 2.0463446 | R5: =(LN(RawData!R6)-LN(RawData!R5))*100 -> 1.1291327 | S5: =+PercentageChange!S5-PercentageChange!R5 -> 5.6846885 | T5: =+PercentageChange!T5-PercentageChange!U5 -> 1.368716 | U5: =(LN(RawData!U6)-LN(RawData!U5))*100 -> -0.19817006 | V5: =+PercentageChange!V5-PercentageChange!U5 -> 7.0119913 | W5: =+PercentageChange!W5-PercentageChange!X5 -> 3.648316 | X5: =(LN(RawData!X6)-LN(RawData!X5))*100 -> 3.7334082 | Y5: =+PercentageChange!Y5-PercentageChange!X5 -> 10.898816 | Z5: =+PercentageChange!Z5-PercentageChange!AA5 -> 5.7287783 | AA5: =(LN(RawData!AA6)-LN(RawData!AA5))*100 -> 4.4011865 | AB5: =+PercentageChange!AB5-PercentageChange!AA5 -> 3.2612482 | AC5: =+PercentageChange!AC5-PercentageChange!AD5 -> 3.2218775 | AD5: =(LN(RawData!AD6)-LN(RawData!AD5))*100 -> 0.25362111 | AE5: =+PercentageChange!AE5-PercentageChange!AD5 -> 6.5602001 | AF5: =+PercentageChange!AF5-PercentageChange!AG5 -> -1.4007434 | AG5: =(LN(RawData!AG6)-LN(RawData!AG5))*100 -> 0.041953698 | AH5: =+PercentageChange!AH5-PercentageChange!AG5 -> 1.8641427 | AI5: =+PercentageChange!AI5-PercentageChange!AJ5 -> 5.3562796 | AJ5: =(LN(RawData!AJ6)-LN(RawData!AJ5))*100 -> -0.23686831 | AK5: =+PercentageChange!AK5-PercentageChange!AJ5 -> 8.7801318 | AL5: =+PercentageChange!AL5-PercentageChange!AM5 -> 14.550115 | AM5: =(LN(RawData!AM6)-LN(RawData!AM5))*100 -> 4.5928855 | AN5: =+PercentageChange!AN5-PercentageChange!AM5 -> 22.455454 | AO5: =+PercentageChange!AO5-PercentageChange!AP5 -> 11.812038 | AP5: =(LN(RawData!AP6)-LN(RawData!AP5))*100 -> 3.633554 | AQ5: =+PercentageChange!AQ5-PercentageChange!AP5 -> 14.430086 | AR5: =+PercentageChange!AR5-PercentageChange!AS5 -> 2.9880495 | AS5: =(LN(RawData!AS6)-LN(RawData!AS5))*100 -> 7.4412822 | AT5: =+PercentageChange!AT5-PercentageChange!AS5 -> 5.04945 | AU5: =+PercentageChange!AU5-PercentageChange!AV5 -> 31.899773 | AV5: =(LN(RawData!AV6)-LN(RawData!AV5))*100 -> 6.2483806 | AW5: =+PercentageChange!AW5-PercentageChange!AV5 -> 24.768004 | AX5: =+PercentageChange!AX5-PercentageChange!AY5 -> 2.100522 | AY5: =(LN(RawData!AY6)-LN(RawData!AY5))*100 -> 1.7761188 | AZ5: =+PercentageChange!AZ5-PercentageChange!AY5 -> 3.1892141 | BA5: =+PercentageChange!BA5-PercentageChange!BB5 -> 1.5420438 | BB5: =(LN(RawData!BB6)-LN(RawData!BB5))*100 -> 1.6861516 | BC5: =+PercentageChange!BC5-PercentageChange!BB5 -> 5.5208952
A6: 2003 | B6: =+PercentageChange!B6-PercentageChange!C6 -> 9.9806448 | C6: =(LN(RawData!C7)-LN(RawData!C6))*100 -> 8.4681539 | D6: =+PercentageChange!D6-PercentageChange!C6 -> 15.214445 | E6: =+PercentageChange!E6-PercentageChange!F6 -> 2.9419178 | F6: =(LN(RawData!F7)-LN(RawData!F6))*100 -> 3.0438873 | G6: =+PercentageChange!G6-PercentageChange!F6 -> 6.9420184 | H6: =+PercentageChange!H6-PercentageChange!I6 -> 13.182638 | I6: =(LN(RawData!I7)-LN(RawData!I6))*100 -> 1.1343706 | J6: =+PercentageChange!J6-PercentageChange!I6 -> 13.117347 | K6: =+PercentageChange!K6-PercentageChange!L6 -> 3.1980499 | L6: =(LN(RawData!L7)-LN(RawData!L6))*100 -> 1.7902639 | M6: =+PercentageChange!M6-PercentageChange!L6 -> 4.0096301 | N6: =+PercentageChange!N6-PercentageChange!O6 -> 2.5698718 | O6: =(LN(RawData!O7)-LN(RawData!O6))*100 -> 9.5655852 | P6: =+PercentageChange!P6-PercentageChange!O6 -> 8.6857707 | Q6: =+PercentageChange!Q6-PercentageChange!R6 -> 1.8422933 | R6: =(LN(RawData!R7)-LN(RawData!R6))*100 -> 0.81979127 | S6: =+PercentageChange!S6-PercentageChange!R6 -> 6.5834455 | T6: =+PercentageChange!T6-PercentageChange!U6 -> 1.3126011 | U6: =(LN(RawData!U7)-LN(RawData!U6))*100 -> -0.702579 | V6: =+PercentageChange!V6-PercentageChange!U6 -> 8.1058157 | W6: =+PercentageChange!W6-PercentageChange!X6 -> 3.7948732 | X6: =(LN(RawData!X7)-LN(RawData!X6))*100 -> 7.5667441 | Y6: =+PercentageChange!Y6-PercentageChange!X6 -> 4.6727297 | Z6: =+PercentageChange!Z6-PercentageChange!AA6 -> 5.3421605 | AA6: =(LN(RawData!AA7)-LN(RawData!AA6))*100 -> 4.6696251 | AB6: =+PercentageChange!AB6-PercentageChange!AA6 -> 1.5555432 | AC6: =+PercentageChange!AC6-PercentageChange!AD6 -> 3.0992802 | AD6: =(LN(RawData!AD7)-LN(RawData!AD6))*100 -> 0.13853089 | AE6: =+PercentageChange!AE6-PercentageChange!AD6 -> 7.2647058 | AF6: =+PercentageChange!AF6-PercentageChange!AG6 -> -1.6207675 | AG6: =(LN(RawData!AG7)-LN(RawData!AG6))*100 -> 1.5234617 | AH6: =+PercentageChange!AH6-PercentageChange!AG6 -> -0.54593854 | AI6: =+PercentageChange!AI6-PercentageChange!AJ6 -> 4.1906212 | AJ6: =(LN(RawData!AJ7)-LN(RawData!AJ6))*100 -> 1.1785723 | AK6: =+PercentageChange!AK6-PercentageChange!AJ6 -> 5.29923 | AL6: =+PercentageChange!AL6-PercentageChange!AM6 -> 12.801616 | AM6: =(LN(RawData!AM7)-LN(RawData!AM6))*100 -> 7.045802 | AN6: =+PercentageChange!AN6-PercentageChange!AM6 -> 25.642749 | AO6: =+PercentageChange!AO6-PercentageChange!AP6 -> 6.1995574 | AP6: =(LN(RawData!AP7)-LN(RawData!AP6))*100 -> 2.9064267 | AQ6: =+PercentageChange!AQ6-PercentageChange!AP6 -> 10.16704 | AR6: =+PercentageChange!AR6-PercentageChange!AS6 -> 3.3918155 | AS6: =(LN(RawData!AS7)-LN(RawData!AS6))*100 -> 3.0987792 | AT6: =+PercentageChange!AT6-PercentageChange!AS6 -> 4.7277592 | AU6: =+PercentageChange!AU6-PercentageChange!AV6 -> 20.936329 | AV6: =(LN(RawData!AV7)-LN(RawData!AV6))*100 -> 5.6032504 | AW6: =+PercentageChange!AW6-PercentageChange!AV6 -> 10.981076 | AX6: =+PercentageChange!AX6-PercentageChange!AY6 -> 2.3645979 | AY6: =(LN(RawData!AY7)-LN(RawData!AY6))*100 -> 3.0980825 | AZ6: =+PercentageChange!AZ6-PercentageChange!AY6 -> 2.7512371 | BA6: =+PercentageChange!BA6-PercentageChange!BB6 -> 1.9550779 | BB6: =(LN(RawData!BB7)-LN(RawData!BB6))*100 -> 2.7572423 | BC6: =+PercentageChange!BC6-PercentageChange!BB6 -> 3.9672121
A7: 2004 | B7: =+PercentageChange!B7-PercentageChange!C7 -> 16.858898 | C7: =(LN(RawData!C8)-LN(RawData!C7))*100 -> 8.6448974 | D7: =+PercentageChange!D7-PercentageChange!C7 -> 18.860405 | E7: =+PercentageChange!E7-PercentageChange!F7 -> 3.1811242 | F7: =(LN(RawData!F8)-LN(RawData!F7))*100 -> 4.137533 | G7: =+PercentageChange!G7-PercentageChange!F7 -> 5.7797138 | H7: =+PercentageChange!H7-PercentageChange!I7 -> 7.4662668 | I7: =(LN(RawData!I8)-LN(RawData!I7))*100 -> 5.6001856 | J7: =+PercentageChange!J7-PercentageChange!I7 -> 14.446074 | K7: =+PercentageChange!K7-PercentageChange!L7 -> 3.2088357 | L7: =(LN(RawData!L8)-LN(RawData!L7))*100 -> 3.0455137 | M7: =+PercentageChange!M7-PercentageChange!L7 -> 5.6182173 | N7: =+PercentageChange!N7-PercentageChange!O7 -> 6.7209881 | O7: =(LN(RawData!O8)-LN(RawData!O7))*100 -> 9.6342568 | P7: =+PercentageChange!P7-PercentageChange!O7 -> 5.3862871 | Q7: =+PercentageChange!Q7-PercentageChange!R7 -> 1.6096508 | R7: =(LN(RawData!R8)-LN(RawData!R7))*100 -> 2.7904551 | S7: =+PercentageChange!S7-PercentageChange!R7 -> 2.6976385 | T7: =+PercentageChange!T7-PercentageChange!U7 -> 1.109419 | U7: =(LN(RawData!U8)-LN(RawData!U7))*100 -> 1.1682376 | V7: =+PercentageChange!V7-PercentageChange!U7 -> 4.3198559 | W7: =+PercentageChange!W7-PercentageChange!X7 -> 5.5675106 | X7: =(LN(RawData!X8)-LN(RawData!X7))*100 -> 7.6247237 | Y7: =+PercentageChange!Y7-PercentageChange!X7 -> 5.8355623 | Z7: =+PercentageChange!Z7-PercentageChange!AA7 -> 8.2047408 | AA7: =(LN(RawData!AA8)-LN(RawData!AA7))*100 -> 4.9084159 | AB7: =+PercentageChange!AB7-PercentageChange!AA7 -> 2.0216319 | AC7: =+PercentageChange!AC7-PercentageChange!AD7 -> 2.6351564 | AD7: =(LN(RawData!AD8)-LN(RawData!AD7))*100 -> 1.4135562 | AE7: =+PercentageChange!AE7-PercentageChange!AD7 -> 4.0745373 | AF7: =+PercentageChange!AF7-PercentageChange!AG7 -> -1.1311397 | AG7: =(LN(RawData!AG8)-LN(RawData!AG7))*100 -> 2.1625628 | AH7: =+PercentageChange!AH7-PercentageChange!AG7 -> -1.0773301 | AI7: =+PercentageChange!AI7-PercentageChange!AJ7 -> 7.8047887 | AJ7: =(LN(RawData!AJ8)-LN(RawData!AJ7))*100 -> 3.5033507 | AK7: =+PercentageChange!AK7-PercentageChange!AJ7 -> 3.6051854 | AL7: =+PercentageChange!AL7-PercentageChange!AM7 -> 18.444555 | AM7: =(LN(RawData!AM8)-LN(RawData!AM7))*100 -> 6.9525576 | AN7: =+PercentageChange!AN7-PercentageChange!AM7 -> 23.572656 | AO7: =+PercentageChange!AO7-PercentageChange!AP7 -> 5.8666674 | AP7: =(LN(RawData!AP8)-LN(RawData!AP7))*100 -> 4.4538854 | AQ7: =+PercentageChange!AQ7-PercentageChange!AP7 -> 8.022876 | AR7: =+PercentageChange!AR7-PercentageChange!AS7 -> 3.0799588 | AS7: =(LN(RawData!AS8)-LN(RawData!AS7))*100 -> 5.0668317 | AT7: =+PercentageChange!AT7-PercentageChange!AS7 -> 0.86628054 | AU7: =+PercentageChange!AU7-PercentageChange!AV7 -> 11.713848 | AV7: =(LN(RawData!AV8)-LN(RawData!AV7))*100 -> 9.3453333 | AW7: =+PercentageChange!AW7-PercentageChange!AV7 -> 11.752635 | AX7: =+PercentageChange!AX7-PercentageChange!AY7 -> 2.5863599 | AY7: =(LN(RawData!AY8)-LN(RawData!AY7))*100 -> 2.3975249 | AZ7: =+PercentageChange!AZ7-PercentageChange!AY7 -> 7.433156 | BA7: =+PercentageChange!BA7-PercentageChange!BB7 -> 2.653567 | BB7: =(LN(RawData!BB8)-LN(RawData!BB7))*100 -> 3.7755907 | BC7: =+PercentageChange!BC7-PercentageChange!BB7 -> 0.87475364
A8: 2005 | B8: =+PercentageChange!B8-PercentageChange!C8 -> 9.8192487 | C8: =(LN(RawData!C9)-LN(RawData!C8))*100 -> 8.4815851 | D8: =+PercentageChange!D8-PercentageChange!C8 -> 10.579888 | E8: =+PercentageChange!E8-PercentageChange!F8 -> 3.7541507 | F8: =(LN(RawData!F9)-LN(RawData!F8))*100 -> 3.1054181 | G8: =+PercentageChange!G8-PercentageChange!F8 -> 4.9016277 | H8: =+PercentageChange!H8-PercentageChange!I8 -> 7.1680687 | I8: =(LN(RawData!I9)-LN(RawData!I8))*100 -> 3.1519326 | J8: =+PercentageChange!J8-PercentageChange!I8 -> 12.104679 | K8: =+PercentageChange!K8-PercentageChange!L8 -> 3.0690574 | L8: =(LN(RawData!L9)-LN(RawData!L8))*100 -> 3.1599964 | M8: =+PercentageChange!M8-PercentageChange!L8 -> 6.2185081 | N8: =+PercentageChange!N8-PercentageChange!O8 -> 3.8294749 | O8: =(LN(RawData!O9)-LN(RawData!O8))*100 -> 10.790859 | P8: =+PercentageChange!P8-PercentageChange!O8 -> 4.1905832 | Q8: =+PercentageChange!Q8-PercentageChange!R8 -> 1.9178329 | R8: =(LN(RawData!R9)-LN(RawData!R8))*100 -> 1.64954 | S8: =+PercentageChange!S8-PercentageChange!R8 -> 5.7235936 | T8: =+PercentageChange!T8-PercentageChange!U8 -> 0.40438858 | U8: =(LN(RawData!U9)-LN(RawData!U8))*100 -> 0.72904317 | V8: =+PercentageChange!V8-PercentageChange!U8 -> 6.6440903 | W8: =+PercentageChange!W8-PercentageChange!X8 -> 5.4695581 | X8: =(LN(RawData!X9)-LN(RawData!X8))*100 -> 7.6251814 | Y8: =+PercentageChange!Y8-PercentageChange!X8 -> 6.2951497 | Z8: =+PercentageChange!Z8-PercentageChange!AA8 -> 13.393445 | AA8: =(LN(RawData!AA9)-LN(RawData!AA8))*100 -> 5.5364423 | AB8: =+PercentageChange!AB8-PercentageChange!AA8 -> 6.6552913 | AC8: =+PercentageChange!AC8-PercentageChange!AD8 -> 1.9906131 | AD8: =(LN(RawData!AD9)-LN(RawData!AD8))*100 -> 0.81452271 | AE8: =+PercentageChange!AE8-PercentageChange!AD8 -> 6.5586108 | AF8: =+PercentageChange!AF8-PercentageChange!AG8 -> -1.2012033 | AG8: =(LN(RawData!AG9)-LN(RawData!AG8))*100 -> 1.7878236 | AH8: =+PercentageChange!AH8-PercentageChange!AG8 -> -1.294716 | AI8: =+PercentageChange!AI8-PercentageChange!AJ8 -> 5.7183251 | AJ8: =(LN(RawData!AJ9)-LN(RawData!AJ8))*100 -> 2.0912277 | AK8: =+PercentageChange!AK8-PercentageChange!AJ8 -> 6.6495302 | AL8: =+PercentageChange!AL8-PercentageChange!AM8 -> 17.629872 | AM8: =(LN(RawData!AM9)-LN(RawData!AM8))*100 -> 6.2035066 | AN8: =+PercentageChange!AN8-PercentageChange!AM8 -> 22.890363 | AO8: =+PercentageChange!AO8-PercentageChange!AP8 -> 5.4459868 | AP8: =(LN(RawData!AP9)-LN(RawData!AP8))*100 -> 5.1425279 | AQ8: =+PercentageChange!AQ8-PercentageChange!AP8 -> 10.05818 | AR8: =+PercentageChange!AR8-PercentageChange!AS8 -> 1.0360163 | AS8: =(LN(RawData!AS9)-LN(RawData!AS8))*100 -> 4.2183078 | AT8: =+PercentageChange!AT8-PercentageChange!AS8 -> 2.5561462 | AU8: =+PercentageChange!AU8-PercentageChange!AV8 -> 6.8456612 | AV8: =(LN(RawData!AV9)-LN(RawData!AV8))*100 -> 8.6107097 | AW8: =+PercentageChange!AW8-PercentageChange!AV8 -> 10.58704 | AX8: =+PercentageChange!AX8-PercentageChange!AY8 -> 2.8930723 | AY8: =(LN(RawData!AY9)-LN(RawData!AY8))*100 -> 2.7020072 | AZ8: =+PercentageChange!AZ8-PercentageChange!AY8 -> 7.0626251 | BA8: =+PercentageChange!BA8-PercentageChange!BB8 -> 3.0873031 | BB8: =(LN(RawData!BB9)-LN(RawData!BB8))*100 -> 3.4242476 | BC8: =+PercentageChange!BC8-PercentageChange!BB8 -> 0.7350383
A9: 2006 | B9: =+PercentageChange!B9-PercentageChange!C9 -> 12.875421 | C9: =(LN(RawData!C10)-LN(RawData!C9))*100 -> 7.7397534 | D9: =+PercentageChange!D9-PercentageChange!C9 -> 13.05143 | E9: =+PercentageChange!E9-PercentageChange!F9 -> 4.9888501 | F9: =(LN(RawData!F10)-LN(RawData!F9))*100 -> 2.718023 | G9: =+PercentageChange!G9-PercentageChange!F9 -> 7.6959758 | H9: =+PercentageChange!H9-PercentageChange!I9 -> 6.5546832 | I9: =(LN(RawData!I10)-LN(RawData!I9))*100 -> 3.8855153 | J9: =+PercentageChange!J9-PercentageChange!I9 -> 12.791938 | K9: =+PercentageChange!K9-PercentageChange!L9 -> 2.537699 | L9: =(LN(RawData!L10)-LN(RawData!L9))*100 -> 2.6037501 | M9: =+PercentageChange!M9-PercentageChange!L9 -> 4.5991027 | N9: =+PercentageChange!N9-PercentageChange!O9 -> 3.8514208 | O9: =(LN(RawData!O10)-LN(RawData!O9))*100 -> 11.974516 | P9: =+PercentageChange!P9-PercentageChange!O9 -> 3.4469338 | Q9: =+PercentageChange!Q9-PercentageChange!R9 -> 2.1324287 | R9: =(LN(RawData!R10)-LN(RawData!R9))*100 -> 2.4198086 | S9: =+PercentageChange!S9-PercentageChange!R9 -> 5.9057508 | T9: =+PercentageChange!T9-PercentageChange!U9 -> 0.39649408 | U9: =(LN(RawData!U10)-LN(RawData!U9))*100 -> 3.7454172 | V9: =+PercentageChange!V9-PercentageChange!U9 -> 4.5801422 | W9: =+PercentageChange!W9-PercentageChange!X9 -> 8.0666558 | X9: =(LN(RawData!X10)-LN(RawData!X9))*100 -> 7.7523222 | Y9: =+PercentageChange!Y9-PercentageChange!X9 -> 9.4699923 | Z9: =+PercentageChange!Z9-PercentageChange!AA9 -> 13.179485 | AA9: =(LN(RawData!AA10)-LN(RawData!AA9))*100 -> 5.3549789 | AB9: =+PercentageChange!AB9-PercentageChange!AA9 -> 9.0204441 | AC9: =+PercentageChange!AC9-PercentageChange!AD9 -> 2.1025937 | AD9: =(LN(RawData!AD10)-LN(RawData!AD9))*100 -> 1.7747966 | AE9: =+PercentageChange!AE9-PercentageChange!AD9 -> 6.5507629 | AF9: =+PercentageChange!AF9-PercentageChange!AG9 -> -0.86575526 | AG9: =(LN(RawData!AG10)-LN(RawData!AG9))*100 -> 1.3630187 | AH9: =+PercentageChange!AH9-PercentageChange!AG9 -> -1.6849079 | AI9: =+PercentageChange!AI9-PercentageChange!AJ9 -> 5.9279288 | AJ9: =(LN(RawData!AJ10)-LN(RawData!AJ9))*100 -> 4.6931424 | AK9: =+PercentageChange!AK9-PercentageChange!AJ9 -> 11.513754 | AL9: =+PercentageChange!AL9-PercentageChange!AM9 -> 14.080841 | AM9: =(LN(RawData!AM10)-LN(RawData!AM9))*100 -> 7.8811811 | AN9: =+PercentageChange!AN9-PercentageChange!AM9 -> 23.42072 | AO9: =+PercentageChange!AO9-PercentageChange!AP9 -> 5.8878505 | AP9: =(LN(RawData!AP10)-LN(RawData!AP9))*100 -> 5.4524231 | AQ9: =+PercentageChange!AQ9-PercentageChange!AP9 -> 15.331718 | AR9: =+PercentageChange!AR9-PercentageChange!AS9 -> -0.22344507 | AS9: =(LN(RawData!AS10)-LN(RawData!AS9))*100 -> 5.1304397 | AT9: =+PercentageChange!AT9-PercentageChange!AS9 -> 2.7374767 | AU9: =+PercentageChange!AU9-PercentageChange!AV9 -> 8.9623188 | AV9: =(LN(RawData!AV10)-LN(RawData!AV9))*100 -> 6.7172438 | AW9: =+PercentageChange!AW9-PercentageChange!AV9 -> 16.469598 | AX9: =+PercentageChange!AX9-PercentageChange!AY9 -> 2.7487081 | AY9: =(LN(RawData!AY10)-LN(RawData!AY9))*100 -> 2.3582488 | AZ9: =+PercentageChange!AZ9-PercentageChange!AY9 -> 9.5979329 | BA9: =+PercentageChange!BA9-PercentageChange!BB9 -> 3.037242 | BB9: =(LN(RawData!BB10)-LN(RawData!BB9))*100 -> 2.7464763 | BC9: =+PercentageChange!BC9-PercentageChange!BB9 -> 2.3716141
A10: 2007 | B10: =+PercentageChange!B10-PercentageChange!C10 -> 13.923941 | C10: =(LN(RawData!C11)-LN(RawData!C10))*100 -> 8.6247885 | D10: =+PercentageChange!D10-PercentageChange!C10 -> 13.230043 | E10: =+PercentageChange!E10-PercentageChange!F10 -> 4.8656631 | F10: =(LN(RawData!F11)-LN(RawData!F10))*100 -> 3.7039419 | G10: =+PercentageChange!G10-PercentageChange!F10 -> 12.31184 | H10: =+PercentageChange!H10-PercentageChange!I10 -> 6.2402223 | I10: =(LN(RawData!I11)-LN(RawData!I10))*100 -> 5.8927848 | J10: =+PercentageChange!J10-PercentageChange!I10 -> 9.131237 | K10: =+PercentageChange!K10-PercentageChange!L10 -> 3.2472472 | L10: =(LN(RawData!L11)-LN(RawData!L10))*100 -> 2.0291769 | M10: =+PercentageChange!M10-PercentageChange!L10 -> 8.3514209 | N10: =+PercentageChange!N10-PercentageChange!O10 -> 7.4640633 | O10: =(LN(RawData!O11)-LN(RawData!O10))*100 -> 13.305131 | P10: =+PercentageChange!P10-PercentageChange!O10 -> 2.8658146 | Q10: =+PercentageChange!Q10-PercentageChange!R10 -> 2.5245016 | R10: =(LN(RawData!R11)-LN(RawData!R10))*100 -> 2.3958062 | S10: =+PercentageChange!S10-PercentageChange!R10 -> 8.2283978 | T10: =+PercentageChange!T10-PercentageChange!U10 -> 1.7547864 | U10: =(LN(RawData!U11)-LN(RawData!U10))*100 -> 2.9330185 | V10: =+PercentageChange!V10-PercentageChange!U10 -> 7.6911856 | W10: =+PercentageChange!W10-PercentageChange!X10 -> 6.7139058 | X10: =(LN(RawData!X11)-LN(RawData!X10))*100 -> 7.3815498 | Y10: =+PercentageChange!Y10-PercentageChange!X10 -> 12.366928 | Z10: =+PercentageChange!Z10-PercentageChange!AA10 -> 10.668684 | AA10: =(LN(RawData!AA11)-LN(RawData!AA10))*100 -> 6.1518549 | AB10: =+PercentageChange!AB10-PercentageChange!AA10 -> 8.6369574 | AC10: =+PercentageChange!AC10-PercentageChange!AD10 -> 2.4487662 | AD10: =(LN(RawData!AD11)-LN(RawData!AD10))*100 -> 1.4761245 | AE10: =+PercentageChange!AE10-PercentageChange!AD10 -> 9.1480796 | AF10: =+PercentageChange!AF10-PercentageChange!AG10 -> -0.70774214 | AG10: =(LN(RawData!AG11)-LN(RawData!AG10))*100 -> 1.4730663 | AH10: =+PercentageChange!AH10-PercentageChange!AG10 -> -1.2981726 | AI10: =+PercentageChange!AI10-PercentageChange!AJ10 -> 5.9473768 | AJ10: =(LN(RawData!AJ11)-LN(RawData!AJ10))*100 -> 2.0565708 | AK10: =+PercentageChange!AK10-PercentageChange!AJ10 -> 7.6700807 | AL10: =+PercentageChange!AL10-PercentageChange!AM10 -> 12.963465 | AM10: =(LN(RawData!AM11)-LN(RawData!AM10))*100 -> 8.1579782 | AN10: =+PercentageChange!AN10-PercentageChange!AM10 -> 28.45156 | AO10: =+PercentageChange!AO10-PercentageChange!AP10 -> 7.9234056 | AP10: =(LN(RawData!AP11)-LN(RawData!AP10))*100 -> 5.2217371 | AQ10: =+PercentageChange!AQ10-PercentageChange!AP10 -> 15.689096 | AR10: =+PercentageChange!AR10-PercentageChange!AS10 -> 2.3903969 | AS10: =(LN(RawData!AS11)-LN(RawData!AS10))*100 -> 5.6376065 | AT10: =+PercentageChange!AT10-PercentageChange!AS10 -> 4.1675552 | AU10: =+PercentageChange!AU10-PercentageChange!AV10 -> 6.0151646 | AV10: =(LN(RawData!AV11)-LN(RawData!AV10))*100 -> 4.920444 | AW10: =+PercentageChange!AW10-PercentageChange!AV10 -> 11.418267 | AX10: =+PercentageChange!AX10-PercentageChange!AY10 -> 2.2275209 | AY10: =(LN(RawData!AY11)-LN(RawData!AY10))*100 -> 2.5865887 | AZ10: =+PercentageChange!AZ10-PercentageChange!AY10 -> 10.05355 | BA10: =+PercentageChange!BA10-PercentageChange!BB10 -> 2.6732078 | BB10: =(LN(RawData!BB11)-LN(RawData!BB10))*100 -> 1.9840453 | BC10: =+PercentageChange!BC10-PercentageChange!BB10 -> 3.9839725
A11: 2008 | B11: =+PercentageChange!B11-PercentageChange!C11 -> 20.840479 | C11: =(LN(RawData!C12)-LN(RawData!C11))*100 -> 3.977088 | D11: =+PercentageChange!D11-PercentageChange!C11 -> 13.290371 | E11: =+PercentageChange!E11-PercentageChange!F11 -> 4.4684818 | F11: =(LN(RawData!F12)-LN(RawData!F11))*100 -> 3.52342 | G11: =+PercentageChange!G11-PercentageChange!F11 -> 14.320069 | H11: =+PercentageChange!H11-PercentageChange!I11 -> 8.4144003 | I11: =(LN(RawData!I12)-LN(RawData!I11))*100 -> 4.9686862 | J11: =+PercentageChange!J11-PercentageChange!I11 -> 12.262561 | K11: =+PercentageChange!K11-PercentageChange!L11 -> 3.9185294 | L11: =(LN(RawData!L12)-LN(RawData!L11))*100 -> 0.99048477 | M11: =+PercentageChange!M11-PercentageChange!L11 -> 10.159366 | N11: =+PercentageChange!N11-PercentageChange!O11 -> 7.5064299 | O11: =(LN(RawData!O12)-LN(RawData!O11))*100 -> 9.2129481 | P11: =+PercentageChange!P11-PercentageChange!O11 -> 6.1331229 | Q11: =+PercentageChange!Q11-PercentageChange!R11 -> 2.339493 | R11: =(LN(RawData!R12)-LN(RawData!R11))*100 -> 0.25462152 | S11: =+PercentageChange!S11-PercentageChange!R11 -> 9.5187204 | T11: =+PercentageChange!T11-PercentageChange!U11 -> 0.90522091 | U11: =(LN(RawData!U12)-LN(RawData!U11))*100 -> 0.95530156 | V11: =+PercentageChange!V11-PercentageChange!U11 -> 8.8180403 | W11: =+PercentageChange!W11-PercentageChange!X11 -> 8.7955653 | X11: =(LN(RawData!X12)-LN(RawData!X11))*100 -> 3.0400177 | Y11: =+PercentageChange!Y11-PercentageChange!X11 -> 16.265049 | Z11: =+PercentageChange!Z11-PercentageChange!AA11 -> 16.678271 | AA11: =(LN(RawData!AA12)-LN(RawData!AA11))*100 -> 5.8398179 | AB11: =+PercentageChange!AB11-PercentageChange!AA11 -> 9.3174366 | AC11: =+PercentageChange!AC11-PercentageChange!AD11 -> 2.3723396 | AD11: =(LN(RawData!AD12)-LN(RawData!AD11))*100 -> -0.96667008 | AE11: =+PercentageChange!AE11-PercentageChange!AD11 -> 10.740012 | AF11: =+PercentageChange!AF11-PercentageChange!AG11 -> -0.91571015 | AG11: =(LN(RawData!AG12)-LN(RawData!AG11))*100 -> -1.2318452 | AH11: =+PercentageChange!AH11-PercentageChange!AG11 -> 1.979685 | AI11: =+PercentageChange!AI11-PercentageChange!AJ11 -> 6.1192758 | AJ11: =(LN(RawData!AJ12)-LN(RawData!AJ11))*100 -> 0.93891027 | AK11: =+PercentageChange!AK11-PercentageChange!AJ11 -> 12.508704 | AL11: =+PercentageChange!AL11-PercentageChange!AM11 -> 16.562899 | AM11: =(LN(RawData!AM12)-LN(RawData!AM11))*100 -> 5.0692822 | AN11: =+PercentageChange!AN11-PercentageChange!AM11 -> 20.709814 | AO11: =+PercentageChange!AO11-PercentageChange!AP11 -> 7.5574263 | AP11: =(LN(RawData!AP12)-LN(RawData!AP11))*100 -> 3.1411879 | AQ11: =+PercentageChange!AQ11-PercentageChange!AP11 -> 14.131579 | AR11: =+PercentageChange!AR11-PercentageChange!AS11 -> 2.7870993 | AS11: =(LN(RawData!AS12)-LN(RawData!AS11))*100 -> 2.9684861 | AT11: =+PercentageChange!AT11-PercentageChange!AS11 -> 7.9668511 | AU11: =+PercentageChange!AU11-PercentageChange!AV11 -> 11.374069 | AV11: =(LN(RawData!AV12)-LN(RawData!AV11))*100 -> 0.81172118 | AW11: =+PercentageChange!AW11-PercentageChange!AV11 -> 17.050222 | AX11: =+PercentageChange!AX11-PercentageChange!AY11 -> 3.3466498 | AY11: =(LN(RawData!AY12)-LN(RawData!AY11))*100 -> -0.22598212 | AZ11: =+PercentageChange!AZ11-PercentageChange!AY11 -> 13.872156 | BA11: =+PercentageChange!BA11-PercentageChange!BB11 -> 1.9083837 | BB11: =(LN(RawData!BB12)-LN(RawData!BB11))*100 -> 0.11352279 | BC11: =+PercentageChange!BC11-PercentageChange!BB11 -> 6.4683591
A12: 2009 | B12: =+PercentageChange!B12-PercentageChange!C12 -> 14.304047 | C12: =(LN(RawData!C13)-LN(RawData!C12))*100 -> -6.1009025 | D12: =+PercentageChange!D12-PercentageChange!C12 -> 15.778956 | E12: =+PercentageChange!E12-PercentageChange!F12 -> 4.8305864 | F12: =(LN(RawData!F13)-LN(RawData!F12))*100 -> 1.8748872 | G12: =+PercentageChange!G12-PercentageChange!F12 -> 8.858849 | H12: =+PercentageChange!H12-PercentageChange!I12 -> 7.058411 | I12: =(LN(RawData!I13)-LN(RawData!I12))*100 -> -0.12589121 | J12: =+PercentageChange!J12-PercentageChange!I12 -> 15.205442 | K12: =+PercentageChange!K12-PercentageChange!L12 -> -2.3523747 | L12: =(LN(RawData!L13)-LN(RawData!L12))*100 -> -2.9584191 | M12: =+PercentageChange!M12-PercentageChange!L12 -> 6.1191547 | N12: =+PercentageChange!N12-PercentageChange!O12 -> -0.20975319 | O12: =(LN(RawData!O13)-LN(RawData!O12))*100 -> 8.9829055 | P12: =+PercentageChange!P12-PercentageChange!O12 -> 14.557593 | Q12: =+PercentageChange!Q12-PercentageChange!R12 -> 0.06660529 | R12: =(LN(RawData!R13)-LN(RawData!R12))*100 -> -2.9154017 | S12: =+PercentageChange!S12-PercentageChange!R12 -> 6.2696951 | T12: =+PercentageChange!T12-PercentageChange!U12 -> 1.8251343 | U12: =(LN(RawData!U13)-LN(RawData!U12))*100 -> -5.8623636 | V12: =+PercentageChange!V12-PercentageChange!U12 -> 9.216657 | W12: =+PercentageChange!W12-PercentageChange!X12 -> 6.8035824 | X12: =(LN(RawData!X13)-LN(RawData!X12))*100 -> 7.5681416 | Y12: =+PercentageChange!Y12-PercentageChange!X12 -> 10.645604 | Z12: =+PercentageChange!Z12-PercentageChange!AA12 -> 7.9501815 | AA12: =(LN(RawData!AA13)-LN(RawData!AA12))*100 -> 4.5249343 | AB12: =+PercentageChange!AB12-PercentageChange!AA12 -> 10.218384 | AC12: =+PercentageChange!AC12-PercentageChange!AD12 -> 1.6649022 | AD12: =(LN(RawData!AD13)-LN(RawData!AD12))*100 -> -5.4254909 | AE12: =+PercentageChange!AE12-PercentageChange!AD12 -> 8.7797843 | AF12: =+PercentageChange!AF12-PercentageChange!AG12 -> -0.57119313 | AG12: =(LN(RawData!AG13)-LN(RawData!AG12))*100 -> -5.8617274 | AH12: =+PercentageChange!AH12-PercentageChange!AG12 -> 7.6416643 | AI12: =+PercentageChange!AI12-PercentageChange!AJ12 -> 5.110636 | AJ12: =(LN(RawData!AJ13)-LN(RawData!AJ12))*100 -> -6.502131 | AK12: =+PercentageChange!AK12-PercentageChange!AJ12 -> 16.941006 | AL12: =+PercentageChange!AL12-PercentageChange!AM12 -> 1.9514474 | AM12: =(LN(RawData!AM13)-LN(RawData!AM12))*100 -> -8.1209989 | AN12: =+PercentageChange!AN12-PercentageChange!AM12 -> 17.834547 | AO12: =+PercentageChange!AO12-PercentageChange!AP12 -> 8.3081549 | AP12: =(LN(RawData!AP13)-LN(RawData!AP12))*100 -> -1.5500404 | AQ12: =+PercentageChange!AQ12-PercentageChange!AP12 -> 7.8631521 | AR12: =+PercentageChange!AR12-PercentageChange!AS12 -> 3.5450578 | AS12: =(LN(RawData!AS13)-LN(RawData!AS12))*100 -> 0.78957364 | AT12: =+PercentageChange!AT12-PercentageChange!AS12 -> 7.071089 | AU12: =+PercentageChange!AU12-PercentageChange!AV12 -> 5.3033047 | AV12: =(LN(RawData!AV13)-LN(RawData!AV12))*100 -> -4.9433488 | AW12: =+PercentageChange!AW12-PercentageChange!AV12 -> 21.39223 | AX12: =+PercentageChange!AX12-PercentageChange!AY12 -> 1.8734527 | AY12: =(LN(RawData!AY13)-LN(RawData!AY12))*100 -> -4.7248406 | AZ12: =+PercentageChange!AZ12-PercentageChange!AY12 -> 14.157307 | BA12: =+PercentageChange!BA12-PercentageChange!BB12 -> 0.61488641 | BB12: =(LN(RawData!BB13)-LN(RawData!BB12))*100 -> -2.6102734 | BC12: =+PercentageChange!BC12-PercentageChange!BB12 -> 10.371316
A13: 2010 | B13: =+PercentageChange!B13-PercentageChange!C13 -> 18.991866 | C13: =(LN(RawData!C14)-LN(RawData!C13))*100 -> 9.6449514 | D13: =+PercentageChange!D13-PercentageChange!C13 -> 15.062275 | E13: =+PercentageChange!E13-PercentageChange!F13 -> 1.1452754 | F13: =(LN(RawData!F14)-LN(RawData!F13))*100 -> 2.2021126 | G13: =+PercentageChange!G13-PercentageChange!F13 -> 3.5438457 | H13: =+PercentageChange!H13-PercentageChange!I13 -> 8.0873178 | I13: =(LN(RawData!I14)-LN(RawData!I13))*100 -> 7.2583193 | J13: =+PercentageChange!J13-PercentageChange!I13 -> 12.644288 | K13: =+PercentageChange!K13-PercentageChange!L13 -> 2.8088185 | L13: =(LN(RawData!L14)-LN(RawData!L13))*100 -> 3.0440029 | M13: =+PercentageChange!M13-PercentageChange!L13 -> 2.2437519 | N13: =+PercentageChange!N13-PercentageChange!O13 -> 6.6549438 | O13: =(LN(RawData!O14)-LN(RawData!O13))*100 -> 10.107418 | P13: =+PercentageChange!P13-PercentageChange!O13 -> 8.656409 | Q13: =+PercentageChange!Q13-PercentageChange!R13 -> 1.0640167 | R13: =(LN(RawData!R14)-LN(RawData!R13))*100 -> 1.9306795 | S13: =+PercentageChange!S13-PercentageChange!R13 -> -3.0471599 | T13: =+PercentageChange!T13-PercentageChange!U13 -> 0.64320278 | U13: =(LN(RawData!U14)-LN(RawData!U13))*100 -> 4.0948858 | V13: =+PercentageChange!V13-PercentageChange!U13 -> -5.2113663 | W13: =+PercentageChange!W13-PercentageChange!X13 -> 10.008088 | X13: =(LN(RawData!X14)-LN(RawData!X13))*100 -> 8.1557726 | Y13: =+PercentageChange!Y13-PercentageChange!X13 -> 6.9472363 | Z13: =+PercentageChange!Z13-PercentageChange!AA13 -> 14.205751 | AA13: =(LN(RawData!AA14)-LN(RawData!AA13))*100 -> 6.0378513 | AB13: =+PercentageChange!AB13-PercentageChange!AA13 -> 5.4720535 | AC13: =+PercentageChange!AC13-PercentageChange!AD13 -> 0.43541125 | AD13: =(LN(RawData!AD14)-LN(RawData!AD13))*100 -> 1.6987844 | AE13: =+PercentageChange!AE13-PercentageChange!AD13 -> -2.8152649 | AF13: =+PercentageChange!AF13-PercentageChange!AG13 -> -1.8986528 | AG13: =(LN(RawData!AG14)-LN(RawData!AG13))*100 -> 4.0161789 | AH13: =+PercentageChange!AH13-PercentageChange!AG13 -> -1.9583349 | AI13: =+PercentageChange!AI13-PercentageChange!AJ13 -> 4.2800494 | AJ13: =(LN(RawData!AJ14)-LN(RawData!AJ13))*100 -> 4.8517123 | AK13: =+PercentageChange!AK13-PercentageChange!AJ13 -> 3.8126917 | AL13: =+PercentageChange!AL13-PercentageChange!AM13 -> 13.270326 | AM13: =(LN(RawData!AM14)-LN(RawData!AM13))*100 -> 4.4016885 | AN13: =+PercentageChange!AN13-PercentageChange!AM13 -> 16.327703 | AO13: =+PercentageChange!AO13-PercentageChange!AP13 -> 5.9479801 | AP13: =(LN(RawData!AP14)-LN(RawData!AP13))*100 -> 2.9944484 | AQ13: =+PercentageChange!AQ13-PercentageChange!AP13 -> 0.41490568 | AR13: =+PercentageChange!AR13-PercentageChange!AS13 -> 2.7006975 | AS13: =(LN(RawData!AS14)-LN(RawData!AS13))*100 -> 6.5832917 | AT13: =+PercentageChange!AT13-PercentageChange!AS13 -> 1.3213508 | AU13: =+PercentageChange!AU13-PercentageChange!AV13 -> 6.7745407 | AV13: =(LN(RawData!AV14)-LN(RawData!AV13))*100 -> 8.0907912 | AW13: =+PercentageChange!AW13-PercentageChange!AV13 -> 6.1250151 | AX13: =+PercentageChange!AX13-PercentageChange!AY13 -> 1.571331 | AY13: =(LN(RawData!AY14)-LN(RawData!AY13))*100 -> 2.2139978 | AZ13: =+PercentageChange!AZ13-PercentageChange!AY13 -> 6.2946973 | BA13: =+PercentageChange!BA13-PercentageChange!BB13 -> 1.2079614 | BB13: =(LN(RawData!BB14)-LN(RawData!BB13))*100 -> 2.659512 | BC13: =+PercentageChange!BC13-PercentageChange!BB13 -> -0.17022574
A14: 2011 | B14: =+PercentageChange!B14-PercentageChange!C14 -> 21.271716 | C14: =(LN(RawData!C15)-LN(RawData!C14))*100 -> 5.8306188 | D14: =+PercentageChange!D14-PercentageChange!C14 -> 22.379136 | E14: =+PercentageChange!E14-PercentageChange!F14 -> 6.0173684 | F14: =(LN(RawData!F15)-LN(RawData!F14))*100 -> 2.3804138 | G14: =+PercentageChange!G14-PercentageChange!F14 -> 6.7372664 | H14: =+PercentageChange!H14-PercentageChange!I14 -> 7.9906627 | I14: =(LN(RawData!I15)-LN(RawData!I14))*100 -> 3.8974751 | J14: =+PercentageChange!J14-PercentageChange!I14 -> 11.95433 | K14: =+PercentageChange!K14-PercentageChange!L14 -> 3.1929342 | L14: =(LN(RawData!L15)-LN(RawData!L14))*100 -> 3.08899 | M14: =+PercentageChange!M14-PercentageChange!L14 -> 4.0005782 | N14: =+PercentageChange!N14-PercentageChange!O14 -> 7.7661578 | O14: =(LN(RawData!O15)-LN(RawData!O14))*100 -> 9.1218476 | P14: =+PercentageChange!P14-PercentageChange!O14 -> 5.3940608 | Q14: =+PercentageChange!Q14-PercentageChange!R14 -> 0.94349528 | R14: =(LN(RawData!R15)-LN(RawData!R14))*100 -> 2.1690067 | S14: =+PercentageChange!S14-PercentageChange!R14 -> -1.0505328 | T14: =+PercentageChange!T14-PercentageChange!U14 -> 1.0638052 | U14: =(LN(RawData!U15)-LN(RawData!U14))*100 -> 3.8501153 | V14: =+PercentageChange!V14-PercentageChange!U14 -> -2.7316414 | W14: =+PercentageChange!W14-PercentageChange!X14 -> 8.3730474 | X14: =(LN(RawData!X15)-LN(RawData!X14))*100 -> 5.1085777 | Y14: =+PercentageChange!Y14-PercentageChange!X14 -> 10.141669 | Z14: =+PercentageChange!Z14-PercentageChange!AA14 -> 7.2003802 | AA14: =(LN(RawData!AA15)-LN(RawData!AA14))*100 -> 5.9869365 | AB14: =+PercentageChange!AB14-PercentageChange!AA14 -> 8.8515474 | AC14: =+PercentageChange!AC14-PercentageChange!AD14 -> 1.5943986 | AD14: =(LN(RawData!AD15)-LN(RawData!AD14))*100 -> 0.70484348 | AE14: =+PercentageChange!AE14-PercentageChange!AD14 -> 0.41363042 | AF14: =+PercentageChange!AF14-PercentageChange!AG14 -> -1.63538 | AG14: =(LN(RawData!AG15)-LN(RawData!AG14))*100 -> 0.02380669 | AH14: =+PercentageChange!AH14-PercentageChange!AG14 -> 2.1537563 | AI14: =+PercentageChange!AI14-PercentageChange!AJ14 -> 5.5147378 | AJ14: =(LN(RawData!AJ15)-LN(RawData!AJ14))*100 -> 3.3860653 | AK14: =+PercentageChange!AK14-PercentageChange!AJ14 -> 11.995897 | AL14: =+PercentageChange!AL14-PercentageChange!AM14 -> 21.881488 | AM14: =(LN(RawData!AM15)-LN(RawData!AM14))*100 -> 4.2101456 | AN14: =+PercentageChange!AN14-PercentageChange!AM14 -> 14.597691 | AO14: =+PercentageChange!AO14-PercentageChange!AP14 -> 5.3910902 | AP14: =(LN(RawData!AP15)-LN(RawData!AP14))*100 -> 3.1193933 | AQ14: =+PercentageChange!AQ14-PercentageChange!AP14 -> 3.4802914 | AR14: =+PercentageChange!AR14-PercentageChange!AS14 -> 1.2737175 | AS14: =(LN(RawData!AS15)-LN(RawData!AS14))*100 -> 3.6193711 | AT14: =+PercentageChange!AT14-PercentageChange!AS14 -> 1.4669034 | AU14: =+PercentageChange!AU14-PercentageChange!AV14 -> 7.8819009 | AV14: =(LN(RawData!AV15)-LN(RawData!AV14))*100 -> 10.616119 | AW14: =+PercentageChange!AW14-PercentageChange!AV14 -> 7.920513 | AX14: =+PercentageChange!AX14-PercentageChange!AY14 -> 2.1655662 | AY14: =(LN(RawData!AY15)-LN(RawData!AY14))*100 -> 1.1385949 | AZ14: =+PercentageChange!AZ14-PercentageChange!AY14 -> -3.0618808 | BA14: =+PercentageChange!BA14-PercentageChange!BB14 -> 2.0421156 | BB14: =(LN(RawData!BB15)-LN(RawData!BB14))*100 -> 1.5522962 | BC14: =+PercentageChange!BC14-PercentageChange!BB14 -> 5.4908728
... A26: 2023 | B26: =+PercentageChange!B26-PercentageChange!C26 -> 84.946637 | C26: =(LN(RawData!C27)-LN(RawData!C26))*100 -> -1.5626475 | D26: =+PercentageChange!D26-PercentageChange!C26 -> 75.22581 | E26: =+PercentageChange!E26-PercentageChange!F26 -> 6.3513393 | F26: =(LN(RawData!F27)-LN(RawData!F26))*100 -> 2.9723722 | G26: =+PercentageChange!G26-PercentageChange!F26 -> 2.1943573 | H26: =+PercentageChange!H26-PercentageChange!I26 -> 4.553721 | I26: =(LN(RawData!I27)-LN(RawData!I26))*100 -> 2.8669868 | J26: =+PercentageChange!J26-PercentageChange!I26 -> 7.3368734 | K26: =+PercentageChange!K26-PercentageChange!L26 -> 1.592494 | L26: =(LN(RawData!L27)-LN(RawData!L26))*100 -> 1.0603528 | M26: =+PercentageChange!M26-PercentageChange!L26 -> 4.6860702 | N26: =+PercentageChange!N26-PercentageChange!O26 -> -0.53700903 | O26: =(LN(RawData!O27)-LN(RawData!O26))*100 -> 5.0693114 | P26: =+PercentageChange!P26-PercentageChange!O26 -> 5.563916 | Q26: =+PercentageChange!Q26-PercentageChange!R26 -> 5.3278489 | R26: =(LN(RawData!R27)-LN(RawData!R26))*100 -> 0.701254 | S26: =+PercentageChange!S26-PercentageChange!R26 -> -0.20653088 | T26: =+PercentageChange!T26-PercentageChange!U26 -> 6.4176031 | U26: =(LN(RawData!U27)-LN(RawData!U26))*100 -> -0.30540045 | V26: =+PercentageChange!V26-PercentageChange!U26 -> 0.80012357 | W26: =+PercentageChange!W26-PercentageChange!X26 -> 1.3572152 | X26: =(LN(RawData!X27)-LN(RawData!X26))*100 -> 7.3101483 | Y26: =+PercentageChange!Y26-PercentageChange!X26 -> 2.7213197 | Z26: =+PercentageChange!Z26-PercentageChange!AA26 -> 1.5214408 | AA26: =(LN(RawData!AA27)-LN(RawData!AA26))*100 -> 4.9248209 | AB26: =+PercentageChange!AB26-PercentageChange!AA26 -> 0.60410324 | AC26: =+PercentageChange!AC26-PercentageChange!AD26 -> 5.1388827 | AD26: =(LN(RawData!AD27)-LN(RawData!AD26))*100 -> 0.91647968 | AE26: =+PercentageChange!AE26-PercentageChange!AD26 -> -0.42175656 | AF26: =+PercentageChange!AF26-PercentageChange!AG26 -> 3.6839152 | AG26: =(LN(RawData!AG27)-LN(RawData!AG26))*100 -> 1.9047985 | AH26: =+PercentageChange!AH26-PercentageChange!AG26 -> 0.043607767 | AI26: =+PercentageChange!AI26-PercentageChange!AJ26 -> 4.3902876 | AJ26: =(LN(RawData!AJ27)-LN(RawData!AJ26))*100 -> 3.1777085 | AK26: =+PercentageChange!AK26-PercentageChange!AJ26 -> 5.2867764 | AL26: =+PercentageChange!AL26-PercentageChange!AM26 -> 6.8346277 | AM26: =(LN(RawData!AM27)-LN(RawData!AM26))*100 -> 3.5367144 | AN26: =+PercentageChange!AN26-PercentageChange!AM26 -> 13.827235 | AO26: =+PercentageChange!AO26-PercentageChange!AP26 -> 4.4253829 | AP26: =(LN(RawData!AP27)-LN(RawData!AP26))*100 -> 0.59985954 | AQ26: =+PercentageChange!AQ26-PercentageChange!AP26 -> 7.7999733 | AR26: =+PercentageChange!AR26-PercentageChange!AS26 -> 2.0430606 | AS26: =(LN(RawData!AS27)-LN(RawData!AS26))*100 -> 1.347612 | AT26: =+PercentageChange!AT26-PercentageChange!AS26 -> 1.4910212 | AU26: =+PercentageChange!AU26-PercentageChange!AV26 -> 51.565444 | AV26: =(LN(RawData!AV27)-LN(RawData!AV26))*100 -> 4.4178274 | AW26: =+PercentageChange!AW26-PercentageChange!AV26 -> 44.533268 | AX26: =+PercentageChange!AX26-PercentageChange!AY26 -> 6.8774637 | AY26: =(LN(RawData!AY27)-LN(RawData!AY26))*100 -> 0.10396379 | AZ26: =+PercentageChange!AZ26-PercentageChange!AY26 -> -0.95946434 | BA26: =+PercentageChange!BA26-PercentageChange!BB26 -> 3.5801367 | BB26: =(LN(RawData!BB27)-LN(RawData!BB26))*100 -> 2.5109114 | BC26: =+PercentageChange!BC26-PercentageChange!BB26 -> -6.0272633

Sheet PercentageChange
A1: DATE | B1: Argentina | C1: Argentina | D1: Argentina | E1: Australia | F1: Australia | G1: Australia | H1: Brazil | I1: Brazil | J1: Brazil | K1: Canada | L1: Canada | M1: Canada | N1: China | O1: China | P1: China | Q1: France | R1: France | S1: France | T1: Germany | U1: Germany | V1: Germany | W1: India | X1: India | Y1: India | Z1: Indonesia | AA1: Indonesia | AB1: Indonesia | AC1: Italy | AD1: Italy | AE1: Italy | AF1: Japan | AG1: Japan | AH1: Japan | AI1: Mexico | AJ1: Mexico | AK1: Mexico | AL1: Russia | AM1: Russia | AN1: Russia | AO1: SouthAfrica | AP1: SouthAfrica | AQ1: SouthAfrica | AR1: SouthKorea | AS1: SouthKorea | AT1: SouthKorea | AU1: Turkiye | AV1: Turkiye | AW1: Turkiye | AX1: UK | AY1: UK | AZ1: UK | BA1: US | BB1: US | BC1: US
A2: YEAR | B2: NGDPg | C2: RealGDP | D2: M3LogDiff | E2: NGDPg | F2: RealGDP | G2: M3LogDiff | H2: NGDPg | I2: RealGDP | J2: M3LogDiff | K2: NGDPg | L2: RealGDP | M2: M3LogDiff | N2: NGDPg | O2: RealGDP | P2: M3LogDiff | Q2: NGDPg | R2: RealGDP | S2: M3LogDiff | T2: NGDPg | U2: RealGDP | V2: M3LogDiff | W2: NGDPg | X2: RealGDP | Y2: M3LogDiff | Z2: NGDPg | AA2: RealGDP | AB2: M3LogDiff | AC2: NGDPg | AD2: RealGDP | AE2: M3LogDiff | AF2: NGDPg | AG2: RealGDP | AH2: M3LogDiff | AI2: NGDPg | AJ2: RealGDP | AK2: M3LogDiff | AL2: NGDPg | AM2: RealGDP | AN2: M3LogDiff | AO2: NGDPg | AP2: RealGDP | AQ2: M3LogDiff | AR2: NGDPg | AS2: RealGDP | AT2: M3LogDiff | AU2: NGDPg | AV2: RealGDP | AW2: M3LogDiff | AX2: NGDPg | AY2: RealGDP | AZ2: M3LogDiff | BA2: NGDPg | BB2: RealGDP | BC2: M3LogDiff
A3: 2000 | B3: =(LN(RawData!B4)-LN(RawData!B3))*100 -> 0.23981619 | C3: =(LN(RawData!C4)-LN(RawData!C3))*100 -> -0.79212801 | D3: =(LN(RawData!D4)-LN(RawData!D3))*100 -> 3.6166705 | E3: =(LN(RawData!E4)-LN(RawData!E3))*100 -> 6.365341 | F3: =(LN(RawData!F4)-LN(RawData!F3))*100 -> 3.8465792 | G3: =(LN(RawData!G4)-LN(RawData!G3))*100 -> 6.8411099 | H3: =(LN(RawData!H4)-LN(RawData!H3))*100 -> 9.7489675 | I3: =(LN(RawData!I4)-LN(RawData!I3))*100 -> 4.2944056 | ... BC3: =(LN(RawData!BC4)-LN(RawData!BC3))*100 -> 5.8967128
A4: 2001 | B4: =(LN(RawData!B5)-LN(RawData!B4))*100 -> -5.610799 | C4: =(LN(RawData!C5)-LN(RawData!C4))*100 -> -4.5089836 | D4: =(LN(RawData!D5)-LN(RawData!D4))*100 -> -8.7046927 | E4: =(LN(RawData!E5)-LN(RawData!E4))*100 -> 6.5315939 | F4: =(LN(RawData!F5)-LN(RawData!F4))*100 -> 2.0048943 | G4: =(LN(RawData!G5)-LN(RawData!G4))*100 -> 8.4746779 | H4: =(LN(RawData!H5)-LN(RawData!H4))*100 -> 9.2846338 | I4: =(LN(RawData!I5)-LN(RawData!I4))*100 -> 1.3803259 | ... BC4: =(LN(RawData!BC5)-LN(RawData!BC4))*100 -> 8.3503321
A5: 2002 | B5: =(LN(RawData!B6)-LN(RawData!B5))*100 -> 15.127702 | C5: =(LN(RawData!C6)-LN(RawData!C5))*100 -> -11.534895 | D5: =(LN(RawData!D6)-LN(RawData!D5))*100 -> -8.8034574 | E5: =(LN(RawData!E6)-LN(RawData!E5))*100 -> 6.7032045 | F5: =(LN(RawData!F6)-LN(RawData!F5))*100 -> 3.9024865 | G5: =(LN(RawData!G6)-LN(RawData!G5))*100 -> 8.4255327 | H5: =(LN(RawData!H6)-LN(RawData!H5))*100 -> 12.355086 | I5: =(LN(RawData!I6)-LN(RawData!I5))*100 -> 3.0077715 | ... BC5: =(LN(RawData!BC6)-LN(RawData!BC5))*100 -> 7.2070468
A6: 2003 | B6: =(LN(RawData!B7)-LN(RawData!B6))*100 -> 18.448799 | C6: =(LN(RawData!C7)-LN(RawData!C6))*100 -> 8.4681539 | D6: =(LN(RawData!D7)-LN(RawData!D6))*100 -> 23.682599 | E6: =(LN(RawData!E7)-LN(RawData!E6))*100 -> 5.9858051 | F6: =(LN(RawData!F7)-LN(RawData!F6))*100 -> 3.0438873 | G6: =(LN(RawData!G7)-LN(RawData!G6))*100 -> 9.9859057 | H6: =(LN(RawData!H7)-LN(RawData!H6))*100 -> 14.317008 | I6: =(LN(RawData!I7)-LN(RawData!I6))*100 -> 1.1343706 | ... BC6: =(LN(RawData!BC7)-LN(RawData!BC6))*100 -> 6.7244543
A7: 2004 | B7: =(LN(RawData!B8)-LN(RawData!B7))*100 -> 25.503795 | C7: =(LN(RawData!C8)-LN(RawData!C7))*100 -> 8.6448974 | D7: =(LN(RawData!D8)-LN(RawData!D7))*100 -> 27.505302 | E7: =(LN(RawData!E8)-LN(RawData!E7))*100 -> 7.3186572 | F7: =(LN(RawData!F8)-LN(RawData!F7))*100 -> 4.137533 | G7: =(LN(RawData!G8)-LN(RawData!G7))*100 -> 9.9172468 | H7: =(LN(RawData!H8)-LN(RawData!H7))*100 -> 13.066452 | I7: =(LN(RawData!I8)-LN(RawData!I7))*100 -> 5.6001856 | ... BC7: =(LN(RawData!BC8)-LN(RawData!BC7))*100 -> 4.6503444
A8: 2005 | B8: =(LN(RawData!B9)-LN(RawData!B8))*100 -> 18.300834 | C8: =(LN(RawData!C9)-LN(RawData!C8))*100 -> 8.4815851 | D8: =(LN(RawData!D9)-LN(RawData!D8))*100 -> 19.061473 | E8: =(LN(RawData!E9)-LN(RawData!E8))*100 -> 6.8595688 | F8: =(LN(RawData!F9)-LN(RawData!F8))*100 -> 3.1054181 | G8: =(LN(RawData!G9)-LN(RawData!G8))*100 -> 8.0070458 | H8: =(LN(RawData!H9)-LN(RawData!H8))*100 -> 10.320001 | I8: =(LN(RawData!I9)-LN(RawData!I8))*100 -> 3.1519326 | ... BC8: =(LN(RawData!BC9)-LN(RawData!BC8))*100 -> 4.1592859
A9: 2006 | B9: =(LN(RawData!B10)-LN(RawData!B9))*100 -> 20.615174 | C9: =(LN(RawData!C10)-LN(RawData!C9))*100 -> 7.7397534 | D9: =(LN(RawData!D10)-LN(RawData!D9))*100 -> 20.791183 | E9: =(LN(RawData!E10)-LN(RawData!E9))*100 -> 7.7068732 | F9: =(LN(RawData!F10)-LN(RawData!F9))*100 -> 2.718023 | G9: =(LN(RawData!G10)-LN(RawData!G9))*100 -> 10.413999 | H9: =(LN(RawData!H10)-LN(RawData!H9))*100 -> 10.440199 | I9: =(LN(RawData!I10)-LN(RawData!I9))*100 -> 3.8855153 | ... BC9: =(LN(RawData!BC10)-LN(RawData!BC9))*100 -> 5.1180904
A10: 2007 | B10: =(LN(RawData!B11)-LN(RawData!B10))*100 -> 22.54873 | C10: =(LN(RawData!C11)-LN(RawData!C10))*100 -> 8.6247885 | D10: =(LN(RawData!D11)-LN(RawData!D10))*100 -> 21.854831 | E10: =(LN(RawData!E11)-LN(RawData!E10))*100 -> 8.569605 | F10: =(LN(RawData!F11)-LN(RawData!F10))*100 -> 3.7039419 | G10: =(LN(RawData!G11)-LN(RawData!G10))*100 -> 16.015782 | H10: =(LN(RawData!H11)-LN(RawData!H10))*100 -> 12.133007 | I10: =(LN(RawData!I11)-LN(RawData!I10))*100 -> 5.8927848 | ... BC10: =(LN(RawData!BC11)-LN(RawData!BC10))*100 -> 5.9680178
A11: 2008 | B11: =(LN(RawData!B12)-LN(RawData!B11))*100 -> 24.817567 | C11: =(LN(RawData!C12)-LN(RawData!C11))*100 -> 3.977088 | D11: =(LN(RawData!D12)-LN(RawData!D11))*100 -> 17.267459 | E11: =(LN(RawData!E12)-LN(RawData!E11))*100 -> 7.9919018 | F11: =(LN(RawData!F12)-LN(RawData!F11))*100 -> 3.52342 | G11: =(LN(RawData!G12)-LN(RawData!G11))*100 -> 17.843489 | H11: =(LN(RawData!H12)-LN(RawData!H11))*100 -> 13.383086 | I11: =(LN(RawData!I12)-LN(RawData!I11))*100 -> 4.9686862 | ... BC11: =(LN(RawData!BC12)-LN(RawData!BC11))*100 -> 6.5818819
A12: 2009 | B12: =(LN(RawData!B13)-LN(RawData!B12))*100 -> 8.2031445 | C12: =(LN(RawData!C13)-LN(RawData!C12))*100 -> -6.1009025 | D12: =(LN(RawData!D13)-LN(RawData!D12))*100 -> 9.6780531 | E12: =(LN(RawData!E13)-LN(RawData!E12))*100 -> 6.7054736 | F12: =(LN(RawData!F13)-LN(RawData!F12))*100 -> 1.8748872 | G12: =(LN(RawData!G13)-LN(RawData!G12))*100 -> 10.733736 | H12: =(LN(RawData!H13)-LN(RawData!H12))*100 -> 6.9325198 | I12: =(LN(RawData!I13)-LN(RawData!I12))*100 -> -0.12589121 | ... BC12: =(LN(RawData!BC13)-LN(RawData!BC12))*100 -> 7.7610429
A13: 2010 | B13: =(LN(RawData!B14)-LN(RawData!B13))*100 -> 28.636817 | C13: =(LN(RawData!C14)-LN(RawData!C13))*100 -> 9.6449514 | D13: =(LN(RawData!D14)-LN(RawData!D13))*100 -> 24.707226 | E13: =(LN(RawData!E14)-LN(RawData!E13))*100 -> 3.347388 | F13: =(LN(RawData!F14)-LN(RawData!F13))*100 -> 2.2021126 | G13: =(LN(RawData!G14)-LN(RawData!G13))*100 -> 5.7459583 | H13: =(LN(RawData!H14)-LN(RawData!H13))*100 -> 15.345637 | I13: =(LN(RawData!I14)-LN(RawData!I13))*100 -> 7.2583193 | ... BC13: =(LN(RawData!BC14)-LN(RawData!BC13))*100 -> 2.4892862
A14: 2011 | B14: =(LN(RawData!B15)-LN(RawData!B14))*100 -> 27.102335 | C14: =(LN(RawData!C15)-LN(RawData!C14))*100 -> 5.8306188 | D14: =(LN(RawData!D15)-LN(RawData!D14))*100 -> 28.209755 | E14: =(LN(RawData!E15)-LN(RawData!E14))*100 -> 8.3977821 | F14: =(LN(RawData!F15)-LN(RawData!F14))*100 -> 2.3804138 | G14: =(LN(RawData!G15)-LN(RawData!G14))*100 -> 9.1176802 | H14: =(LN(RawData!H15)-LN(RawData!H14))*100 -> 11.888138 | I14: =(LN(RawData!I15)-LN(RawData!I14))*100 -> 3.8974751 | ... BC14: =(LN(RawData!BC15)-LN(RawData!BC14))*100 -> 7.043169
... A26: 2023 | B26: =(LN(RawData!B27)-LN(RawData!B26))*100 -> 83.383989 | C26: =(LN(RawData!C27)-LN(RawData!C26))*100 -> -1.5626475 | D26: =(LN(RawData!D27)-LN(RawData!D26))*100 -> 73.663163 | E26: =(LN(RawData!E27)-LN(RawData!E26))*100 -> 9.3237115 | F26: =(LN(RawData!F27)-LN(RawData!F26))*100 -> 2.9723722 | G26: =(LN(RawData!G27)-LN(RawData!G26))*100 -> 5.1667294 | H26: =(LN(RawData!H27)-LN(RawData!H26))*100 -> 7.4207078 | I26: =(LN(RawData!I27)-LN(RawData!I26))*100 -> 2.8669868 | ... BC26: =(LN(RawData!BC27)-LN(RawData!BC26))*100 -> -3.5163519

Sheet RawData
A1: Date | B1: Argentina | C1: Argentina | D1: Argentina | E1: Australia | F1: Australia | G1: Australia | H1: Brazil | I1: Brazil | J1: Brazil | K1: Canada | L1: Canada | M1: Canada | N1: China | O1: China | P1: China | Q1: France | R1: France | S1: France | T1: Germany | U1: Germany | V1: Germany | W1: India | X1: India | Y1: India | Z1: Indonesia | AA1: Indonesia | AB1: Indonesia | AC1: Italy | AD1: Italy | AE1: Italy | AF1: Japan | AG1: Japan | AH1: Japan | AI1: Mexico | AJ1: Mexico | AK1: Mexico | AL1: Russia | AM1: Russia | AN1: Russia | AO1: SouthAfrica | AP1: SouthAfrica | AQ1: SouthAfrica | AR1: SouthKorea | AS1: SouthKorea | AT1: SouthKorea | AU1: Turkiye | AV1: Turkiye | AW1: Turkiye | AX1: UK | AY1: UK | AZ1: UK | BA1: US | BB1: US | BC1: US
A2: Year | B2: GDP | C2: Real | D2: M3 | E2: GDP | F2: Real | G2: M3 | H2: GDP | I2: Real | J2: M3 | K2: GDP | L2: Real | M2: M3 | N2: GDP | O2: Real | P2: M3 | Q2: GDP | R2: Real | S2: M3 | T2: GDP | U2: Real | V2: M3 | W2: GDP | X2: Real | Y2: M3 | Z2: GDP | AA2: Real | AB2: M3 | AC2: GDP | AD2: Real | AE2: M3 | AF2: GDP | AG2: Real | AH2: M3 | AI2: GDP | AJ2: Real | AK2: M3 | AL2: GDP | AM2: Real | AN2: M3 | AO2: GDP | AP2: Real | AQ2: M3 | AR2: GDP | AS2: Real | AT2: M3 | AU2: GDP | AV2: Real | AW2: M3 | AX2: GDP | AY2: Real | AZ2: M3 | BA2: GDP | BB2: Real | BC2: M3
A3: 1999 | B3: 283523000000 | C3: 483773071300 | D3: 91371792 | E3: 621807000000 | F3: 1235185000000 | G3: 403100 | H3: 1087710456100 | I3: 2593107378800 | J3: 416766.61 | K3: 1007917000000 | L3: 1414784443000 | M3: 614942.33 | N3: 9056437577700 | O3: 17705941500500 | P3: 11196032 | Q3: 1400999000000 | R3: 1774862991000 | S3: 4544253.1 | T3: 2059480000000 | U3: 2483283310000 | V3: 4544253.1 | W3: 19882615729000 | X3: 41666935662000 | Y3: 10177500 | Z3: 1.0997316e+15 | AA3: 3.9284441e+15 | AB3: 6.2415133e+08 | AC3: 1175149500000 | AD3: 1599723200000 | AE3: 4544253.1 | AF3: 528069900000000 | AG3: 469590420459000 | AH3: 9.4965931e+08 | AI3: 6034995116000 | AJ3: 16958941075000 | AK3: 1365240.8 | AL3: 4823233500000 | AM3: 44463967080000 | AN3: 765.10833 | AO3: 925690425000 | AP3: 2712790594800 | AQ3: 451951.64 | AR3: 591453000000000 | AS3: 828483400000000 | AT3: 836722900 | AU3: 107374257900 | AV3: 687564129200 | AW3: 32346.718 | AX3: 1043248000000 | AY3: 1438113735000 | AZ3: 837937 | BA3: 9631172000000 | BB3: 13180243872000 | BC3: 4518000
A4: 2000 | B4: 284203750000 | C4: 479956106900 | D4: 94736894 | E4: 662674000000 | F4: 1283623000000 | G4: 431641.67 | H4: 1199092070900 | I4: 2706891619700 | J4: 516056.05 | K4: 1106063000000 | L4: 1487483696000 | M4: 661828.33 | N4: 10028013925300 | O4: 19209192472300 | P4: 12665882 | Q4: 1478585000000 | R4: 1844502744000 | S4: 4801939.6 | T4: 2109090000000 | U4: 2555609010000 | V4: 4801939.6 | W4: 21398856906000 | X4: 43267358976000 | Y4: 11780833 | Z4: 1.3897699e+15 | AA4: 4.1217262e+15 | AB4: 6.8588108e+08 | AC4: 1241512900000 | AD4: 1660304000000 | AE4: 4801939.6 | AF4: 535417700000000 | AG4: 482572940520000 | AH4: 968125500 | AI4: 7016603942000 | AJ4: 17811854384000 | AK4: 1655152.6 | AL4: 7305646300000 | AM4: 48910393496000 | AN4: 1224.3917 | AO4: 1053138033600 | AP4: 2826727799800 | AQ4: 490133.31 | AR4: 651634400000000 | AS4: 903550900000000 | AT4: 884971250 | AU4: 171494210000 | AV4: 735234598400 | AW4: 54957.217 | AX4: 1100752000000 | AY4: 1500221942000 | AZ4: 905747.75 | BA4: 10250952000000 | BB4: 13717679619000 | BC4: 4792425
A5: 2001 | B5: 268696750000 | C5: 458795611600 | D5: 86839066 | E5: 707402000000 | F5: 1309618000000 | G5: 469816.67 | H5: 1315755467800 | I5: 2744514608900 | J5: 593647.77 | K5: 1144535000000 | L5: 1515375475000 | M5: 698379.33 | N5: 11086312304600 | O5: 20810419560100 | P5: 14616452 | Q5: 1538200000000 | R5: 1881092540000 | S5: 5205663 | T5: 2172540000000 | U5: 2598580770000 | V5: 5205663 | W5: 23152429571000 | X5: 45354561777000 | Y5: 13740000 | Z5: 1.646322e+15 | AA5: 4.2719e+15 | AB5: 7.8674733e+08 | AC5: 1304136800000 | AD5: 1692702700000 | AE5: 5205663 | AF5: 531653900000000 | AG5: 484436171177000 | AH5: 983625000 | AI5: 7437107660000 | AJ5: 17731550484000 | AK5: 2121632.8 | AL5: 8943582400000 | AM5: 51404848619000 | AN5: 1779.7667 | AO5: 1165940572900 | AP5: 2903049450400 | AQ5: 561212.58 | AR5: 707021300000000 | AS5: 947394800000000 | AT5: 968941300 | AU5: 247266207500 | AV5: 692958560800 | AW5: 95906.501 | AX5: 1146135000000 | AY5: 1538908781000 | AZ5: 998448.83 | BA5: 10581929000000 | BB5: 13848757308000 | BC5: 5209791.7
A6: 2002 | B6: 312580000000 | C6: 408812193300 | D6: 79521070 | E6: 756446000000 | F6: 1361736000000 | G6: 511116.67 | H6: 1488787255200 | I6: 2828317315700 | J6: 652046.32 | K6: 1193687000000 | L6: 1560825455000 | M6: 739895.08 | N6: 12171742474800 | O6: 22711166448500 | P6: 17066325 | Q6: 1587829000000 | R6: 1902452938000 | S6: 5572731.2 | T6: 2198120000000 | U6: 2593436260000 | V6: 5572731.2 | W6: 24926137847000 | X6: 47079838114000 | Y6: 15905000 | Z6: 1.8218334e+15 | AA6: 4.464113e+15 | AB6: 8.4940108e+08 | AC6: 1350258900000 | AD6: 1697001200000 | AE6: 5572731.2 | AF6: 524478700000000 | AG6: 484639452702000 | AH6: 1.0025537e+09 | AI6: 7827757973000 | AJ6: 17689599763000 | AK6: 2310857.4 | AL6: 10830500000000 | AM6: 53820872345000 | AN6: 2332.5583 | AO6: 1360679275100 | AP6: 3010473149200 | AQ6: 672321.18 | AR6: 784741300000000 | AS6: 1.0205824e+15 | AT6: 1.0978526e+09 | AU6: 362109647600 | AV6: 737638602700 | AW6: 130782.76 | AX6: 1191439000000 | AY6: 1566485805000 | AZ6: 1049276.6 | BA6: 10929108000000 | BB6: 14084248131000 | BC6: 5599125
